2025-08-01 22:27:41 - root - INFO - Logging initialized. Log file: logs/bot_run_20250801_222741.log
2025-08-01 22:27:41 - __main__ - INFO - ‚úÖ Loaded YAML configuration from: instant_booking_config.yaml
2025-08-01 22:27:41 - __main__ - INFO - ‚ö° Fast mode: True
2025-08-01 22:27:41 - __main__ - INFO - üéØ Instant booking: True
2025-08-01 22:27:41 - __main__ - INFO - ‚è∞ Check interval: 45s
2025-08-01 22:27:41 - __main__ - INFO - üëÅÔ∏è Headless mode: False
2025-08-01 22:27:41 - __main__ - INFO - üëÅÔ∏è Using YAML config headless setting: False
2025-08-01 22:27:41 - __main__ - INFO - üöÄ Starting Amazon Shift Bot [ID: 964eb915]
2025-08-01 22:27:41 - selenium.webdriver.common.driver_finder - DEBUG - Skipping Selenium Manager; path to chrome driver specified in Service class: /Users/lovepreetgill/.pyenv/versions/3.13.4/lib/python3.13/site-packages/seleniumbase/drivers/uc_driver
2025-08-01 22:27:41 - selenium.webdriver.common.service - DEBUG - Started executable: `/Users/lovepreetgill/.pyenv/versions/3.13.4/lib/python3.13/site-packages/seleniumbase/drivers/uc_driver` in a child process with pid: 69516 using 0 to output -1
2025-08-01 22:27:43 - asyncio - DEBUG - Using selector: KqueueSelector
2025-08-01 22:27:43 - selenium.webdriver.common.service - DEBUG - Started executable: `/Users/lovepreetgill/.pyenv/versions/3.13.4/lib/python3.13/site-packages/seleniumbase/drivers/uc_driver` in a child process with pid: 69552 using 0 to output -1
2025-08-01 22:27:43 - services.session_service - INFO - üîê Establishing Amazon session
2025-08-01 22:27:44 - seleniumbase.undetected.reactor - DEBUG - Exception ignored: HTTPConnectionPool(host='localhost', port=49161): Max retries exceeded with url: /session/0c4dc2c0b78682b2722cffe3bd132050/se/log (Caused by NewConnectionError('<urllib3.connection.HTTPConnection object at 0x1076e3100>: Failed to establish a new connection: [Errno 61] Connection refused'))
2025-08-01 22:27:45 - selenium.webdriver.common.service - DEBUG - Started executable: `/Users/lovepreetgill/.pyenv/versions/3.13.4/lib/python3.13/site-packages/seleniumbase/drivers/uc_driver` in a child process with pid: 69609 using 0 to output -1
2025-08-01 22:27:51 - session_manager - INFO - üìä Added 15/15 cookies
2025-08-01 22:27:51 - session_manager - DEBUG - Failed to restore local storage persist:alert: Message: javascript error: missing ) after argument list
  (Session info: chrome=138.0.7204.184)
Stacktrace:
0   uc_driver                           0x00000001055dfa98 uc_driver + 6167192
1   uc_driver                           0x00000001055d704a uc_driver + 6131786
2   uc_driver                           0x0000000105063e00 uc_driver + 417280
3   uc_driver                           0x000000010506ab5e uc_driver + 445278
4   uc_driver                           0x000000010506d82a uc_driver + 456746
5   uc_driver                           0x000000010510420a uc_driver + 1073674
6   uc_driver                           0x00000001050dbc92 uc_driver + 908434
7   uc_driver                           0x000000010510310c uc_driver + 1069324
8   uc_driver                           0x00000001050dba63 uc_driver + 907875
9   uc_driver                           0x00000001050a80c7 uc_driver + 696519
10  uc_driver                           0x00000001050a8d31 uc_driver + 699697
11  uc_driver                           0x000000010559dc50 uc_driver + 5897296
12  uc_driver                           0x00000001055a1cc9 uc_driver + 5913801
13  uc_driver                           0x0000000105578962 uc_driver + 5744994
14  uc_driver                           0x00000001055a264f uc_driver + 5916239
15  uc_driver                           0x0000000105567634 uc_driver + 5674548
16  uc_driver                           0x00000001055c4628 uc_driver + 6055464
17  uc_driver                           0x00000001055c47f0 uc_driver + 6055920
18  uc_driver                           0x00000001055d6be1 uc_driver + 6130657
19  libsystem_pthread.dylib             0x00007ff811914df1 _pthread_start + 99
20  libsystem_pthread.dylib             0x00007ff811910857 thread_start + 15

2025-08-01 22:27:52 - seleniumbase.undetected.reactor - DEBUG - Exception ignored: HTTPConnectionPool(host='localhost', port=49161): Max retries exceeded with url: /session/a96a06626cdb3a58b6ef0bb46c45987e/se/log (Caused by NewConnectionError('<urllib3.connection.HTTPConnection object at 0x1078f0af0>: Failed to establish a new connection: [Errno 61] Connection refused'))
2025-08-01 22:27:53 - seleniumbase.undetected.reactor - DEBUG - Exception ignored: HTTPConnectionPool(host='localhost', port=49161): Max retries exceeded with url: /session/a96a06626cdb3a58b6ef0bb46c45987e/se/log (Caused by NewConnectionError('<urllib3.connection.HTTPConnection object at 0x1078f1480>: Failed to establish a new connection: [Errno 61] Connection refused'))
2025-08-01 22:27:54 - seleniumbase.undetected.reactor - DEBUG - Exception ignored: HTTPConnectionPool(host='localhost', port=49161): Max retries exceeded with url: /session/a96a06626cdb3a58b6ef0bb46c45987e/se/log (Caused by NewConnectionError('<urllib3.connection.HTTPConnection object at 0x10765f570>: Failed to establish a new connection: [Errno 61] Connection refused'))
2025-08-01 22:27:55 - selenium.webdriver.common.service - DEBUG - Started executable: `/Users/lovepreetgill/.pyenv/versions/3.13.4/lib/python3.13/site-packages/seleniumbase/drivers/uc_driver` in a child process with pid: 69767 using 0 to output -1
2025-08-01 22:28:03 - session_manager - INFO - ‚úÖ Session valid - found: div[data-test-component="StencilReactRow"]
2025-08-01 22:28:03 - session_manager - INFO - ‚úÖ Session restored successfully for lovepreet@teamarora.com
2025-08-01 22:28:05 - seleniumbase.undetected.reactor - DEBUG - Exception ignored: HTTPConnectionPool(host='localhost', port=49161): Max retries exceeded with url: /session/864b2086fa7099615538b8f919eb63d7/se/log (Caused by NewConnectionError('<urllib3.connection.HTTPConnection object at 0x1078f0160>: Failed to establish a new connection: [Errno 61] Connection refused'))
2025-08-01 22:28:06 - seleniumbase.undetected.reactor - DEBUG - Exception ignored: HTTPConnectionPool(host='localhost', port=49161): Max retries exceeded with url: /session/864b2086fa7099615538b8f919eb63d7/se/log (Caused by NewConnectionError('<urllib3.connection.HTTPConnection object at 0x1078f2030>: Failed to establish a new connection: [Errno 61] Connection refused'))
2025-08-01 22:28:07 - seleniumbase.undetected.reactor - DEBUG - Exception ignored: HTTPConnectionPool(host='localhost', port=49161): Max retries exceeded with url: /session/864b2086fa7099615538b8f919eb63d7/se/log (Caused by NewConnectionError('<urllib3.connection.HTTPConnection object at 0x1078f29c0>: Failed to establish a new connection: [Errno 61] Connection refused'))
2025-08-01 22:28:08 - selenium.webdriver.common.service - DEBUG - Started executable: `/Users/lovepreetgill/.pyenv/versions/3.13.4/lib/python3.13/site-packages/seleniumbase/drivers/uc_driver` in a child process with pid: 69941 using 0 to output -1
2025-08-01 22:28:09 - services.session_service - DEBUG - Session valid - found: div[data-test-component="StencilReactRow"]
2025-08-01 22:28:09 - services.session_service - INFO - ‚úÖ Existing session validated successfully
2025-08-01 22:28:09 - enhanced_integrated_monitor - INFO - üîî Enhanced Discord notifier initialized successfully
2025-08-01 22:28:09 - enhanced_integrated_monitor - INFO - ‚úÖ Loaded filter configuration from /Users/lovepreetgill/developer/amazon_shift_bot/filter_config.yaml
2025-08-01 22:28:09 - enhanced_integrated_monitor - INFO - üöÄ Starting Enhanced Job Monitor
2025-08-01 22:28:09 - enhanced_integrated_monitor - INFO - ‚úÖ Enhanced components initialized successfully
2025-08-01 22:28:09 - enhanced_integrated_monitor - INFO - üìä Starting monitoring cycle 1
2025-08-01 22:28:09 - enhanced_integrated_monitor - INFO - üîç Attempt 1: Processing URL 1/3: https://hiring.amazon.com/app#/jobSearch
2025-08-01 22:28:10 - seleniumbase.undetected.reactor - DEBUG - Exception ignored: HTTPConnectionPool(host='localhost', port=49161): Max retries exceeded with url: /session/2283c82e186e895f5f1d1d23185870f2/se/log (Caused by NewConnectionError('<urllib3.connection.HTTPConnection object at 0x1078f3020>: Failed to establish a new connection: [Errno 61] Connection refused'))
2025-08-01 22:28:11 - seleniumbase.undetected.reactor - DEBUG - Exception ignored: HTTPConnectionPool(host='localhost', port=49161): Max retries exceeded with url: /session/2283c82e186e895f5f1d1d23185870f2/se/log (Caused by NewConnectionError('<urllib3.connection.HTTPConnection object at 0x1078f38a0>: Failed to establish a new connection: [Errno 61] Connection refused'))
2025-08-01 22:28:12 - selenium.webdriver.common.service - DEBUG - Started executable: `/Users/lovepreetgill/.pyenv/versions/3.13.4/lib/python3.13/site-packages/seleniumbase/drivers/uc_driver` in a child process with pid: 70211 using 0 to output -1
